System check identified no issues (0 silenced).
September 11, 2017 - 02:03:12
Django version 1.11.4, using settings 'SecondProject.settings'
Starting development server at http://127.0.0.1:8000/
Quit the server with CTRL-BREAK.
[11/Sep/2017 02:03:15] "POST /admin/users_list/ HTTP/1.1" 200 7153
[11/Sep/2017 02:03:15] "GET /static/js/create_user.js HTTP/1.1" 304 0
[11/Sep/2017 02:03:15] "GET /static/vendors/bootstrap/css/bootstrap.min.css.map HTTP/1.1" 200 366144
[11/Sep/2017 02:03:19] "GET /admin/get_user_form/6 HTTP/1.1" 200 1852
[11/Sep/2017 02:03:22] "POST /admin/users_list/ HTTP/1.1" 200 7153
[11/Sep/2017 02:03:22] "POST /admin/user/create/6 HTTP/1.1" 200 3848
Traceback (most recent call last):
  File "C:\Users\Raylen\AppData\Local\Programs\Python\Python35\lib\wsgiref\handlers.py", line 138, in run
    self.finish_response()
  File "C:\Users\Raylen\AppData\Local\Programs\Python\Python35\lib\wsgiref\handlers.py", line 180, in finish_response
    self.write(data)
  File "C:\Users\Raylen\AppData\Local\Programs\Python\Python35\lib\wsgiref\handlers.py", line 274, in write
    self.send_headers()
  File "C:\Users\Raylen\AppData\Local\Programs\Python\Python35\lib\wsgiref\handlers.py", line 332, in send_headers
    self.send_preamble()
  File "C:\Users\Raylen\AppData\Local\Programs\Python\Python35\lib\wsgiref\handlers.py", line 255, in send_preamble
    ('Date: %s\r\n' % format_date_time(time.time())).encode('iso-8859-1')
  File "C:\Users\Raylen\AppData\Local\Programs\Python\Python35\lib\wsgiref\handlers.py", line 453, in _write
    result = self.stdout.write(data)
  File "C:\Users\Raylen\AppData\Local\Programs\Python\Python35\lib\socket.py", line 593, in write
    return self._sock.send(b)
ConnectionAbortedError: [WinError 10053] Программа на вашем хост-компьютере разорвала установленное подключение
[11/Sep/2017 02:03:22] "POST /admin/user/create/6 HTTP/1.1" 500 59
----------------------------------------
Exception happened during processing of request from ('127.0.0.1', 64262)
Traceback (most recent call last):
  File "C:\Users\Raylen\AppData\Local\Programs\Python\Python35\lib\wsgiref\handlers.py", line 138, in run
    self.finish_response()
  File "C:\Users\Raylen\AppData\Local\Programs\Python\Python35\lib\wsgiref\handlers.py", line 180, in finish_response
    self.write(data)
  File "C:\Users\Raylen\AppData\Local\Programs\Python\Python35\lib\wsgiref\handlers.py", line 274, in write
    self.send_headers()
  File "C:\Users\Raylen\AppData\Local\Programs\Python\Python35\lib\wsgiref\handlers.py", line 332, in send_headers
    self.send_preamble()
  File "C:\Users\Raylen\AppData\Local\Programs\Python\Python35\lib\wsgiref\handlers.py", line 255, in send_preamble
    ('Date: %s\r\n' % format_date_time(time.time())).encode('iso-8859-1')
  File "C:\Users\Raylen\AppData\Local\Programs\Python\Python35\lib\wsgiref\handlers.py", line 453, in _write
    result = self.stdout.write(data)
  File "C:\Users\Raylen\AppData\Local\Programs\Python\Python35\lib\socket.py", line 593, in write
    return self._sock.send(b)
ConnectionAbortedError: [WinError 10053] Программа на вашем хост-компьютере разорвала установленное подключение

During handling of the above exception, another exception occurred:

Traceback (most recent call last):
  File "C:\Users\Raylen\AppData\Local\Programs\Python\Python35\lib\wsgiref\handlers.py", line 141, in run
    self.handle_error()
  File "C:\Users\Raylen\AppData\Local\Programs\Python\Python35\lib\site-packages\django\core\servers\basehttp.py", line 88, in handle_error
    super(ServerHandler, self).handle_error()
  File "C:\Users\Raylen\AppData\Local\Programs\Python\Python35\lib\wsgiref\handlers.py", line 368, in handle_error
    self.finish_response()
  File "C:\Users\Raylen\AppData\Local\Programs\Python\Python35\lib\wsgiref\handlers.py", line 180, in finish_response
    self.write(data)
  File "C:\Users\Raylen\AppData\Local\Programs\Python\Python35\lib\wsgiref\handlers.py", line 274, in write
    self.send_headers()
  File "C:\Users\Raylen\AppData\Local\Programs\Python\Python35\lib\wsgiref\handlers.py", line 331, in send_headers
    if not self.origin_server or self.client_is_modern():
  File "C:\Users\Raylen\AppData\Local\Programs\Python\Python35\lib\wsgiref\handlers.py", line 344, in client_is_modern
    return self.environ['SERVER_PROTOCOL'].upper() != 'HTTP/0.9'
TypeError: 'NoneType' object is not subscriptable

During handling of the above exception, another exception occurred:

Traceback (most recent call last):
  File "C:\Users\Raylen\AppData\Local\Programs\Python\Python35\lib\socketserver.py", line 625, in process_request_thread
    self.finish_request(request, client_address)
  File "C:\Users\Raylen\AppData\Local\Programs\Python\Python35\lib\socketserver.py", line 354, in finish_request
    self.RequestHandlerClass(request, client_address, self)
  File "C:\Users\Raylen\AppData\Local\Programs\Python\Python35\lib\socketserver.py", line 681, in __init__
    self.handle()
  File "C:\Users\Raylen\AppData\Local\Programs\Python\Python35\lib\site-packages\django\core\servers\basehttp.py", line 155, in handle
    handler.run(self.server.get_app())
  File "C:\Users\Raylen\AppData\Local\Programs\Python\Python35\lib\wsgiref\handlers.py", line 144, in run
    self.close()
  File "C:\Users\Raylen\AppData\Local\Programs\Python\Python35\lib\wsgiref\simple_server.py", line 36, in close
    self.status.split(' ',1)[0], self.bytes_sent
AttributeError: 'NoneType' object has no attribute 'split'
----------------------------------------